<?xml version="1.0" encoding="UTF-8"?>
<!-- Generated by org.testng.reporters.JUnitReportReporter -->
<testsuite skipped="0" hostname="BDC6-DX-6BYDNK2" name="Day1.SoftAssertion" tests="1" failures="1" timestamp="17 Sep 2019 10:09:01 GMT" time="0.046" errors="0">
  <testcase name="method1" time="0.046" classname="Day1.SoftAssertion">
    <failure type="java.lang.AssertionError" message="The following asserts failed:
	expected [11] but found [10],
	expected [hello] but found [Hello]">
      <![CDATA[java.lang.AssertionError: The following asserts failed:
expected [11] but found [10],
expected [hello] but found [Hello]
at org.testng.asserts.SoftAssert.assertAll(SoftAssert.java:43)
at Day1.SoftAssertion.method1(SoftAssertion.java:15)
at sun.reflect.NativeMethodAccessorImpl.invoke0(Native Method)
at sun.reflect.NativeMethodAccessorImpl.invoke(Unknown Source)
at sun.reflect.DelegatingMethodAccessorImpl.invoke(Unknown Source)
at java.lang.reflect.Method.invoke(Unknown Source)
at org.testng.internal.MethodInvocationHelper.invokeMethod(MethodInvocationHelper.java:124)
at org.testng.internal.Invoker.invokeMethod(Invoker.java:580)
at org.testng.internal.Invoker.invokeTestMethod(Invoker.java:716)
at org.testng.internal.Invoker.invokeTestMethods(Invoker.java:988)
at org.testng.internal.TestMethodWorker.invokeTestMethods(TestMethodWorker.java:125)
at org.testng.internal.TestMethodWorker.run(TestMethodWorker.java:109)
at java.util.concurrent.ThreadPoolExecutor.runWorker(Unknown Source)
at java.util.concurrent.ThreadPoolExecutor$Worker.run(Unknown Source)
at java.lang.Thread.run(Unknown Source)
]]>
    </failure>
  </testcase> <!-- method1 -->
</testsuite> <!-- Day1.SoftAssertion -->
